Workbook

Sheet Summary
B2: Innomesh Portal v4 — Regression Test Plan
B3: Environment: https://v4-portal.dev.innomate.innomesh.com.au | Build: Innomesh v4.0.0 | Author: Chakrala Sai Charan | Created: 10/06/2026 (from live UI exploration)
B4: Scope: every actionable item post-login — navigation, dashboards, Hotlist (alerts & incidents), Vitals, Insights, Assets, Information, Integrations, Rooms, Axis AI, Administration, RBAC, NFR, plus live defects & historical edge cases.
B6: Module / Sheet | C6: Total | D6: P1 | E6: Pass | F6: Fail | G6: Blocked | H6: Not Tested | I6: % Executed | J6: % Pass (of executed)
B7: Global & Navigation | C7: =COUNTA('Global & Navigation'!$A$5:$A$39) -> 35 | D7: =COUNTIF('Global & Navigation'!$F$5:$F$39,"P1") -> 11 | E7: =COUNTIF('Global & Navigation'!$I$5:$I$39,"Pass") -> 0 | F7: =COUNTIF('Global & Navigation'!$I$5:$I$39,"Fail") -> 0 | G7: =COUNTIF('Global & Navigation'!$I$5:$I$39,"Blocked") -> 0 | H7: =COUNTIF('Global & Navigation'!$I$5:$I$39,"Not Tested") -> 35 | I7: =IF(C7=0,0,(C7-H7)/C7) -> 0 | J7: =IF((C7-H7)=0,0,E7/(C7-H7)) -> 0
B8: Dashboard | C8: =COUNTA(Dashboard!$A$5:$A$19) -> 15 | D8: =COUNTIF(Dashboard!$F$5:$F$19,"P1") -> 6 | E8: =COUNTIF(Dashboard!$I$5:$I$19,"Pass") -> 0 | F8: =COUNTIF(Dashboard!$I$5:$I$19,"Fail") -> 0 | G8: =COUNTIF(Dashboard!$I$5:$I$19,"Blocked") -> 0 | H8: =COUNTIF(Dashboard!$I$5:$I$19,"Not Tested") -> 15 | I8: =IF(C8=0,0,(C8-H8)/C8) -> 0 | J8: =IF((C8-H8)=0,0,E8/(C8-H8)) -> 0
B9: Alerts (Hotlist) | C9: =COUNTA('Alerts (Hotlist)'!$A$5:$A$52) -> 48 | D9: =COUNTIF('Alerts (Hotlist)'!$F$5:$F$52,"P1") -> 23 | E9: =COUNTIF('Alerts (Hotlist)'!$I$5:$I$52,"Pass") -> 0 | F9: =COUNTIF('Alerts (Hotlist)'!$I$5:$I$52,"Fail") -> 0 | G9: =COUNTIF('Alerts (Hotlist)'!$I$5:$I$52,"Blocked") -> 0 | H9: =COUNTIF('Alerts (Hotlist)'!$I$5:$I$52,"Not Tested") -> 48 | I9: =IF(C9=0,0,(C9-H9)/C9) -> 0 | J9: =IF((C9-H9)=0,0,E9/(C9-H9)) -> 0
B10: Incidents (Hotlist) | C10: =COUNTA('Incidents (Hotlist)'!$A$5:$A$27) -> 23 | D10: =COUNTIF('Incidents (Hotlist)'!$F$5:$F$27,"P1") -> 15 | E10: =COUNTIF('Incidents (Hotlist)'!$I$5:$I$27,"Pass") -> 0 | F10: =COUNTIF('Incidents (Hotlist)'!$I$5:$I$27,"Fail") -> 0 | G10: =COUNTIF('Incidents (Hotlist)'!$I$5:$I$27,"Blocked") -> 0 | H10: =COUNTIF('Incidents (Hotlist)'!$I$5:$I$27,"Not Tested") -> 23 | I10: =IF(C10=0,0,(C10-H10)/C10) -> 0 | J10: =IF((C10-H10)=0,0,E10/(C10-H10)) -> 0
B11: Vitals | C11: =COUNTA(Vitals!$A$5:$A$25) -> 21 | D11: =COUNTIF(Vitals!$F$5:$F$25,"P1") -> 11 | E11: =COUNTIF(Vitals!$I$5:$I$25,"Pass") -> 0 | F11: =COUNTIF(Vitals!$I$5:$I$25,"Fail") -> 0 | G11: =COUNTIF(Vitals!$I$5:$I$25,"Blocked") -> 0 | H11: =COUNTIF(Vitals!$I$5:$I$25,"Not Tested") -> 21 | I11: =IF(C11=0,0,(C11-H11)/C11) -> 0 | J11: =IF((C11-H11)=0,0,E11/(C11-H11)) -> 0
B12: Insights | C12: =COUNTA(Insights!$A$5:$A$21) -> 17 | D12: =COUNTIF(Insights!$F$5:$F$21,"P1") -> 6 | E12: =COUNTIF(Insights!$I$5:$I$21,"Pass") -> 0 | F12: =COUNTIF(Insights!$I$5:$I$21,"Fail") -> 0 | G12: =COUNTIF(Insights!$I$5:$I$21,"Blocked") -> 0 | H12: =COUNTIF(Insights!$I$5:$I$21,"Not Tested") -> 17 | I12: =IF(C12=0,0,(C12-H12)/C12) -> 0 | J12: =IF((C12-H12)=0,0,E12/(C12-H12)) -> 0
B13: Assets | C13: =COUNTA(Assets!$A$5:$A$27) -> 23 | D13: =COUNTIF(Assets!$F$5:$F$27,"P1") -> 13 | E13: =COUNTIF(Assets!$I$5:$I$27,"Pass") -> 0 | F13: =COUNTIF(Assets!$I$5:$I$27,"Fail") -> 0 | G13: =COUNTIF(Assets!$I$5:$I$27,"Blocked") -> 0 | H13: =COUNTIF(Assets!$I$5:$I$27,"Not Tested") -> 23 | I13: =IF(C13=0,0,(C13-H13)/C13) -> 0 | J13: =IF((C13-H13)=0,0,E13/(C13-H13)) -> 0
B14: Information | C14: =COUNTA(Information!$A$5:$A$16) -> 12 | D14: =COUNTIF(Information!$F$5:$F$16,"P1") -> 5 | E14: =COUNTIF(Information!$I$5:$I$16,"Pass") -> 0 | F14: =COUNTIF(Information!$I$5:$I$16,"Fail") -> 0 | G14: =COUNTIF(Information!$I$5:$I$16,"Blocked") -> 0 | H14: =COUNTIF(Information!$I$5:$I$16,"Not Tested") -> 12 | I14: =IF(C14=0,0,(C14-H14)/C14) -> 0 | J14: =IF((C14-H14)=0,0,E14/(C14-H14)) -> 0
B15: Integrations | C15: =COUNTA(Integrations!$A$5:$A$18) -> 14 | D15: =COUNTIF(Integrations!$F$5:$F$18,"P1") -> 6 | E15: =COUNTIF(Integrations!$I$5:$I$18,"Pass") -> 0 | F15: =COUNTIF(Integrations!$I$5:$I$18,"Fail") -> 0 | G15: =COUNTIF(Integrations!$I$5:$I$18,"Blocked") -> 0 | H15: =COUNTIF(Integrations!$I$5:$I$18,"Not Tested") -> 14 | I15: =IF(C15=0,0,(C15-H15)/C15) -> 0 | J15: =IF((C15-H15)=0,0,E15/(C15-H15)) -> 0
B16: Rooms | C16: =COUNTA(Rooms!$A$5:$A$25) -> 21 | D16: =COUNTIF(Rooms!$F$5:$F$25,"P1") -> 12 | E16: =COUNTIF(Rooms!$I$5:$I$25,"Pass") -> 0 | F16: =COUNTIF(Rooms!$I$5:$I$25,"Fail") -> 0 | G16: =COUNTIF(Rooms!$I$5:$I$25,"Blocked") -> 0 | H16: =COUNTIF(Rooms!$I$5:$I$25,"Not Tested") -> 21 | I16: =IF(C16=0,0,(C16-H16)/C16) -> 0 | J16: =IF((C16-H16)=0,0,E16/(C16-H16)) -> 0
B17: Axis AI | C17: =COUNTA('Axis AI'!$A$5:$A$16) -> 12 | D17: =COUNTIF('Axis AI'!$F$5:$F$16,"P1") -> 4 | E17: =COUNTIF('Axis AI'!$I$5:$I$16,"Pass") -> 0 | F17: =COUNTIF('Axis AI'!$I$5:$I$16,"Fail") -> 0 | G17: =COUNTIF('Axis AI'!$I$5:$I$16,"Blocked") -> 0 | H17: =COUNTIF('Axis AI'!$I$5:$I$16,"Not Tested") -> 12 | I17: =IF(C17=0,0,(C17-H17)/C17) -> 0 | J17: =IF((C17-H17)=0,0,E17/(C17-H17)) -> 0
B18: Administration | C18: =COUNTA(Administration!$A$5:$A$44) -> 40 | D18: =COUNTIF(Administration!$F$5:$F$44,"P1") -> 28 | E18: =COUNTIF(Administration!$I$5:$I$44,"Pass") -> 0 | F18: =COUNTIF(Administration!$I$5:$I$44,"Fail") -> 0 | G18: =COUNTIF(Administration!$I$5:$I$44,"Blocked") -> 0 | H18: =COUNTIF(Administration!$I$5:$I$44,"Not Tested") -> 40 | I18: =IF(C18=0,0,(C18-H18)/C18) -> 0 | J18: =IF((C18-H18)=0,0,E18/(C18-H18)) -> 0
B19: RBAC & Permissions | C19: =COUNTA('RBAC & Permissions'!$A$5:$A$23) -> 19 | D19: =COUNTIF('RBAC & Permissions'!$F$5:$F$23,"P1") -> 14 | E19: =COUNTIF('RBAC & Permissions'!$I$5:$I$23,"Pass") -> 0 | F19: =COUNTIF('RBAC & Permissions'!$I$5:$I$23,"Fail") -> 0 | G19: =COUNTIF('RBAC & Permissions'!$I$5:$I$23,"Blocked") -> 0 | H19: =COUNTIF('RBAC & Permissions'!$I$5:$I$23,"Not Tested") -> 19 | I19: =IF(C19=0,0,(C19-H19)/C19) -> 0 | J19: =IF((C19-H19)=0,0,E19/(C19-H19)) -> 0
B20: RM-Portal Consistency | C20: =COUNTA('RM-Portal Consistency'!$A$5:$A$27) -> 23 | D20: =COUNTIF('RM-Portal Consistency'!$F$5:$F$27,"P1") -> 11 | E20: =COUNTIF('RM-Portal Consistency'!$I$5:$I$27,"Pass") -> 0 | F20: =COUNTIF('RM-Portal Consistency'!$I$5:$I$27,"Fail") -> 0 | G20: =COUNTIF('RM-Portal Consistency'!$I$5:$I$27,"Blocked") -> 0 | H20: =COUNTIF('RM-Portal Consistency'!$I$5:$I$27,"Not Tested") -> 23 | I20: =IF(C20=0,0,(C20-H20)/C20) -> 0 | J20: =IF((C20-H20)=0,0,E20/(C20-H20)) -> 0
B21: Non-Functional | C21: =COUNTA('Non-Functional'!$A$5:$A$24) -> 20 | D21: =COUNTIF('Non-Functional'!$F$5:$F$24,"P1") -> 7 | E21: =COUNTIF('Non-Functional'!$I$5:$I$24,"Pass") -> 0 | F21: =COUNTIF('Non-Functional'!$I$5:$I$24,"Fail") -> 0 | G21: =COUNTIF('Non-Functional'!$I$5:$I$24,"Blocked") -> 0 | H21: =COUNTIF('Non-Functional'!$I$5:$I$24,"Not Tested") -> 20 | I21: =IF(C21=0,0,(C21-H21)/C21) -> 0 | J21: =IF((C21-H21)=0,0,E21/(C21-H21)) -> 0
B22: Known Issues & Edge Cases | C22: =COUNTA('Known Issues & Edge Cases'!$A$5:$A$21) -> 17 | D22: =COUNTIF('Known Issues & Edge Cases'!$F$5:$F$21,"P1") -> 6 | E22: =COUNTIF('Known Issues & Edge Cases'!$I$5:$I$21,"Pass") -> 0 | F22: =COUNTIF('Known Issues & Edge Cases'!$I$5:$I$21,"Fail") -> 0 | G22: =COUNTIF('Known Issues & Edge Cases'!$I$5:$I$21,"Blocked") -> 0 | H22: =COUNTIF('Known Issues & Edge Cases'!$I$5:$I$21,"Not Tested") -> 17 | I22: =IF(C22=0,0,(C22-H22)/C22) -> 0 | J22: =IF((C22-H22)=0,0,E22/(C22-H22)) -> 0
B23: TOTAL | C23: =SUM(C7:C22) -> 360 | D23: =SUM(D7:D22) -> 178 | E23: =SUM(E7:E22) -> 0 | F23: =SUM(F7:F22) -> 0 | G23: =SUM(G7:G22) -> 0 | H23: =SUM(H7:H22) -> 360 | I23: =IF(C23=0,0,(C23-H23)/C23) -> 0 | J23: =IF((C23-H23)=0,0,E23/(C23-H23)) -> 0
B25: How to use
B26: • Status column has a dropdown: Not Tested / Pass / Fail / Blocked / N/A — colour-coded automatically.
B27: • Priority: P1 = must pass every release (smoke/blocker), P2 = standard regression, P3 = nice-to-verify.
B28: • Type: Smoke (critical path), Regression (feature behaviour), Edge (boundary/unusual), Negative (error handling).
B29: • Automation column marks the intended harness (Playwright / Manual / API). Filter by it when scoping an automation sprint.
B30: • Each sheet has autofilter + frozen header; use the Summary table above for live execution progress.
B31: • 'Known Issues & Edge Cases' tracks open dev defects found on 10/06/2026 and historical edge cases — retest these every release.

Sheet Global & Navigation
A1: Global & Navigation — Regression Tests
A2: Authentication, navigation, top bar, user menu, global chrome
A4: Test ID | B4: Category | C4: Test Case | D4: Steps | E4: Expected Result | F4: Priority | G4: Type | H4: Automation | I4: Status | J4: Tested By | K4: Date | L4: Notes / Defect
A5: GLB-001 | B5: Authentication | C5: Google SSO sign-in with corporate account | D5: 1. Open portal URL in incognito 2. Complete Google authentication with innomate.com.au account | E5: User lands on Dashboard; user card (bottom-left) shows correct name and email | F5: P1 | G5: Smoke | H5: Manual | I5: Not Tested
A6: GLB-002 | B6: Authentication | C6: Unauthenticated access redirects to login | D6: 1. Clear cookies / open incognito 2. Navigate directly to /hotlist/alerts/active | E6: User is redirected to the Google auth flow; after login user is returned to the requested page (or Dashboard) | F6: P1 | G6: Regression | H6: Playwright | I6: Not Tested
A7: GLB-003 | B7: Authentication | C7: Sign Out from user menu | D7: 1. Click user card bottom-left 2. Click Sign Out | E7: Session is terminated; user is returned to login; back button does not restore an authenticated session | F7: P1 | G7: Regression | H7: Playwright | I7: Not Tested
A8: GLB-004 | B8: Authentication | C8: Session expiry handling | D8: 1. Leave the portal idle past token expiry (or invalidate token) 2. Interact with any page | E8: User is prompted to re-authenticate gracefully; no infinite spinners or silent empty data | F8: P2 | G8: Edge | H8: Manual | I8: Not Tested
A9: GLB-005 | B9: Authentication | C9: Terms of Service acceptance for first-time user | D9: 1. Login with a brand-new user account | E9: Terms & Privacy popup appears; no page is accessible until accepted; popup does not reappear on next login | F9: P1 | G9: Regression | H9: Playwright | I9: Not Tested
A10: GLB-006 | B10: Navigation | C10: All sidebar sections render for full-permission user | D10: 1. Login as admin user 2. Inspect sidebar | E10: Sections: Dashboard; Monitoring (Hotlist, Vitals); Analytics (Insights); Management (Assets, Information, Integrations, Rooms); AI (Axis AI); System (Administration) | F10: P1 | G10: Smoke | H10: Playwright | I10: Not Tested
A11: GLB-007 | B11: Navigation | C11: Hotlist expands to Alerts and Incidents | D11: 1. Click Hotlist in sidebar | E11: Sub-items Alerts and Incidents appear; clicking each loads the corresponding page and highlights active item | F11: P1 | G11: Smoke | H11: Playwright | I11: Not Tested
A12: GLB-008 | B12: Navigation | C12: Vitals expands to all 9 dashboards | D12: 1. Click Vitals in sidebar | E12: Sub-items: Infrastructure, Rooms, Network, Pulse, Sight, VNOC, Pods-2, Pods-3, Pods (custom dashboards reflect tenant config) | F12: P2 | G12: Regression | H12: Playwright | I12: Not Tested
A13: GLB-009 | B13: Navigation | C13: Insights expands to all sub-dashboards | D13: 1. Click Insights in sidebar | E13: Sub-items: Rooms, Usage, Alerts, Proactive Support, Sight, Ops, Consumption, ECU Custom Insight, INPOD (tenant-custom items included) | F13: P2 | G13: Regression | H13: Playwright | I13: Not Tested
A14: GLB-010 | B14: Navigation | C14: Sidebar collapse/expand via hamburger | D14: 1. Click hamburger icon top-left 2. Click again | E14: Sidebar collapses to icons / hides and restores; main content reflows without overlap; state persists across page navigation | F14: P3 | G14: Regression | H14: Playwright | I14: Not Tested
A15: GLB-011 | B15: Navigation | C15: Sidebar scrolls independently with all sections expanded | D15: 1. Expand every collapsible section | E15: Sidebar gains its own scrollbar; user card remains pinned at bottom; no items unreachable | F15: P3 | G15: Edge | H15: Playwright | I15: Not Tested
A16: GLB-012 | B16: Navigation | C16: Browser back/forward navigation | D16: 1. Visit Dashboard > Alerts > an alert detail 2. Press browser Back twice, Forward twice | E16: Each step restores the correct page and state; no blank screens or stale data | F16: P2 | G16: Regression | H16: Playwright | I16: Not Tested
... A39: GLB-035 | B39: Analytics | C39: Google Analytics page-view tracking | D39: 1. With googleAnalyticsId configured, navigate several routes 2. Inspect gtag page_view events | E39: GA script loads once; page_view fired per route change with correct page_path; no GA when ID not configured | F39: P3 | G39: Regression | H39: Manual | I39: Not Tested

Sheet Dashboard
A1: Dashboard — Regression Tests
A2: Landing dashboard widgets, KPIs and cross-links
A4: Test ID | B4: Category | C4: Test Case | D4: Steps | E4: Expected Result | F4: Priority | G4: Type | H4: Automation | I4: Status | J4: Tested By | K4: Date | L4: Notes / Defect
A5: DSH-001 | B5: KPI Cards | C5: Five KPI cards render with data | D5: 1. Open Dashboard 2. Wait for load | E5: Cards show Active Alerts, Critical, Rooms Online, Rooms Occupied, Active Incidents with numeric values and coloured top borders; no card remains a skeleton after load completes. KNOWN ISSUE: cards intermittently stuck as skeletons | F5: P1 | G5: Smoke | H5: Playwright | I5: Not Tested
A6: DSH-002 | B6: KPI Cards | C6: KPI values match module pages | D6: 1. Note Active Alerts and Active Incidents counts 2. Open Hotlist > Alerts (ACTIVE tab) and Incidents (ACTIVE tab) | E6: Dashboard counts equal the tab counts on the respective pages (within refresh window) | F6: P1 | G6: Regression | H6: Playwright | I6: Not Tested
A7: DSH-003 | B7: Alerts by Severity | C7: Donut chart renders and reconciles | D7: 1. Inspect Alerts by Severity widget | E7: Donut shows total active count centred; legend High/Medium/Low segments sum to total; Claimed + Unclaimed footer figures sum to total | F7: P1 | G7: Regression | H7: Playwright | I7: Not Tested
A8: DSH-004 | B8: Alerts by Severity | C8: 'View Hotlist' link | D8: 1. Click View Hotlist -> | E8: Navigates to /hotlist/alerts/active with no filter loss | F8: P2 | G8: Regression | H8: Playwright | I8: Not Tested
A9: DSH-005 | B9: Room Status | C9: Room Status donut renders | D9: 1. Inspect Room Status widget | E9: Donut renders; Occupied / Maintenance footer counts match Rooms module figures; 'View Rooms ->' navigates to Rooms | F9: P2 | G9: Regression | H9: Playwright | I9: Not Tested
A10: DSH-006 | B10: Active Incidents | C10: Incident breakdown widget | D10: 1. Inspect Active Incidents widget | E10: OPEN INCIDENTS total displayed; New / In Progress / On Hold rows sum to the total; 'View Incidents ->' navigates to Incidents page | F10: P1 | G10: Regression | H10: Playwright | I10: Not Tested
A11: DSH-007 | B11: Alert Trend | C11: 7-day alert trend chart | D11: 1. Inspect Alert Trend widget 2. Toggle legend items (Critical/High/Low/Medium) | E11: Chart plots last 7 days with date axis; legend toggles hide/show series; tooltip values on hover are plausible vs alert history | F11: P2 | G11: Regression | H11: Playwright | I11: Not Tested
A12: DSH-008 | B12: Alert Trend | C12: 'View Insights' link | D12: 1. Click View Insights -> | E12: Navigates to Insights > Alerts dashboard | F12: P3 | G12: Regression | H12: Playwright | I12: Not Tested
A13: DSH-009 | B13: Top Alerting Rooms | C13: Top alerting rooms bar chart | D13: 1. Inspect Top Alerting Rooms widget | E13: Up to 5 rooms with bar + count, sorted descending; counts match per-room alert totals in Hotlist; 'View Rooms ->' works | F13: P2 | G13: Regression | H13: Playwright | I13: Not Tested
A14: DSH-010 | B14: Recent Alerts | C14: Recent Critical & High Alerts table | D14: 1. Inspect bottom table | E14: Columns Time, Room, Device, Category, Severity, Summary; only CRITICAL/HIGH severities listed, newest first; 'View All ->' opens Hotlist | F14: P2 | G14: Regression | H14: Playwright | I14: Not Tested
A15: DSH-011 | B15: Recent Alerts | C15: Row navigates to alert detail | D15: 1. Click a row in Recent Critical & High Alerts | E15: Opens the alert detail page for that alert | F15: P2 | G15: Regression | H15: Playwright | I15: Not Tested
A16: DSH-012 | B16: Refresh | C16: Dashboard 'Updated <time>' stamp | D16: 1. Note Updated stamp top-right 2. Leave page open past refresh interval | E16: Widgets re-fetch periodically; Updated stamp advances; no flicker/duplication of widgets | F16: P3 | G16: Regression | H16: Manual | I16: Not Tested
... A19: DSH-015 | B19: Permissions | C19: Dashboard widgets for restricted user | D19: 1. Login as user without Hotlist/Rooms permissions | E19: Widgets tied to unauthorised modules are hidden or show a permission message; links to unauthorised modules are not offered | F19: P1 | G19: Regression | H19: Manual | I19: Not Tested

Sheet Alerts (Hotlist)
A1: Alerts (Hotlist) — Regression Tests
A2: Hotlist > Alerts: tabs, table, bulk & row actions, saved views, alert detail
A4: Test ID | B4: Category | C4: Test Case | D4: Steps | E4: Expected Result | F4: Priority | G4: Type | H4: Automation | I4: Status | J4: Tested By | K4: Date | L4: Notes / Defect
A5: ALR-001 | B5: Tabs | C5: Active tab loads with count | D5: 1. Open Hotlist > Alerts | E5: ACTIVE tab selected by default with row count badge (e.g. ACTIVE : 3380); table populated; count equals 'N alerts' label on the right | F5: P1 | G5: Smoke | H5: Playwright | I5: Not Tested
A6: ALR-002 | B6: Tabs | C6: Resolved / Suppressed / History tabs | D6: 1. Click each tab | E6: URL changes to /hotlist/alerts/{active|resolved|suppressed|history}; per-tab counts appear after lazy load (spinner in tab while counting); table content matches tab | F6: P1 | G6: Regression | H6: Playwright | I6: Not Tested
A7: ALR-003 | B7: Tabs | C7: History capped at 1000 | D7: 1. Open HISTORY tab in a tenancy with >1000 historical alerts | E7: Count shows 1000 (cap); pagination works through all pages; export warns/includes capped set consistently | F7: P3 | G7: Edge | H7: Playwright | I7: Not Tested
A8: ALR-004 | B8: Tabs | C8: Suppressed alerts show suppression context | D8: 1. Open SUPPRESSED tab | E8: Rows show SUPPRESSED badge; Owner column shows the suppressing user as a link; suppression correlates to room/asset definition (In Maintenance, Is Portable etc.) | F8: P2 | G8: Regression | H8: Manual | I8: Not Tested
A9: ALR-005 | B9: Table | C9: Default sort and column sorting | D9: 1. Verify default sort (Severity desc) 2. Click each sortable header twice | E9: Each column sorts asc/desc with indicator; severity sorts by rank (Critical>High>Medium>Low>Notice) not alphabetically | F9: P2 | G9: Regression | H9: Playwright | I9: Not Tested
A10: ALR-006 | B10: Table | C10: Severity badges colour-coded | D10: 1. Inspect Severity column | E10: CRITICAL/HIGH red, MEDIUM orange, LOW yellow, NOTICE grey (per design); colours consistent in dark mode | F10: P3 | G10: Regression | H10: Playwright | I10: Not Tested
A11: ALR-007 | B11: Table | C11: Unclaimed owner highlighted | D11: 1. Inspect Owner column | E11: 'Unclaimed' renders in red; claimed alerts show owner name | F11: P3 | G11: Regression | H11: Playwright | I11: Not Tested
A12: ALR-008 | B12: Table | C12: Pagination controls | D12: 1. Change Rows per page (15 default) 2. Use first/prev/next/last | E12: Page size options apply; 'Showing X to Y of Z entries' accurate; navigation buttons disable at bounds | F12: P2 | G12: Regression | H12: Playwright | I12: Not Tested
A13: ALR-009 | B13: Search | C13: Search filters across fields | D13: 1. Type a room name, then an asset name, then a description fragment | E13: Result set narrows live (debounced); count label updates; clearing search restores full set | F13: P1 | G13: Regression | H13: Playwright | I13: Not Tested
A14: ALR-010 | B14: Search | C14: Search with no matches | D14: 1. Search a nonsense string | E14: Empty state message; 0 alerts; no error | F14: P2 | G14: Negative | H14: Playwright | I14: Not Tested
A15: ALR-011 | B15: Saved Views | C15: Save View As / Recall View / Delete View | D15: 1. Apply search + column changes 2. Save icon > Save View As, name it 3. Reset, then Recall View > select it 4. Save icon > Delete View | E15: View saved and listed in Recall View dropdown; recalling restores filters/columns; delete removes it (red action with confirm) | F15: P1 | G15: Regression | H15: Playwright | I15: Not Tested
A16: ALR-012 | B16: Saved Views | C16: Saved view name collision / special chars | D16: 1. Save two views with the same name; use emoji/long names | E16: Duplicate names rejected or disambiguated; long names truncated gracefully in dropdown | F16: P3 | G16: Edge | H16: Manual | I16: Not Tested
... A52: ALR-048 | B52: AI | C52: Alert AI diagnosis (v3 parity gap) | D52: 1. v3 offered session-based AI diagnosis on Pulse alerts (/alerts/{id}/ai/query, /ai/diagnosis) 2. Check v4 alert detail for equivalent | E52: PARITY CHECK: confirm whether alert-level AI diagnosis exists in v4 (vs Axis AI page only); if dropped, document as accepted delta | F52: P2 | G52: Edge | H52: Manual | I52: Not Tested

Sheet Incidents (Hotlist)
A1: Incidents (Hotlist) — Regression Tests
A2: Hotlist > Incidents: lifecycle, create wizard, ServiceNow sync, rules
A4: Test ID | B4: Category | C4: Test Case | D4: Steps | E4: Expected Result | F4: Priority | G4: Type | H4: Automation | I4: Status | J4: Tested By | K4: Date | L4: Notes / Defect
A5: INC-001 | B5: Tabs | C5: Tab counts and content | D5: 1. Open Hotlist > Incidents 2. Click ACTIVE / RESOLVED / ON HOLD / HISTORY | E5: Counts per tab (e.g. ACTIVE : 228); URL updates per tab; rows match the state shown | F5: P1 | G5: Smoke | H5: Playwright | I5: Not Tested
A6: INC-002 | B6: Trend | C6: SHOW TREND collapsible | D6: 1. Click SHOW TREND | E6: Incident trend chart expands above the table; collapsible toggles; data consistent with incident history | F6: P3 | G6: Regression | H6: Playwright | I6: Not Tested
A7: INC-003 | B7: Table | C7: Incident table columns | D7: 1. Inspect table | E7: Priority badge (CRITICAL/HIGH/MODERATE/LOW), State badge (NEW/IN PROGRESS/ON HOLD/RESOLVED), Description, Room, Site, Assigned To, Created, Last Updated, ID (INC# + external ServiceNow link icon), Comments count; all sortable | F7: P1 | G7: Regression | H7: Playwright | I7: Not Tested
A8: INC-004 | B8: Table | C8: ServiceNow external link icon | D8: 1. Click the external-link icon next to an INC number | E8: Opens the matching incident in ServiceNow in a new tab | F8: P2 | G8: Regression | H8: Manual | I8: Not Tested
A9: INC-005 | B9: Create | C9: Create Incident wizard — step 1 validation | D9: 1. Click + Create 2. Leave Incident Name empty; try Next | E9: Next disabled until required fields completed; Incident Name marked * ; Cancel/X closes without creating | F9: P1 | G9: Regression | H9: Playwright | I9: Not Tested
A10: INC-006 | B10: Create | C10: Scope radio switches selector | D10: 1. In wizard choose Scope = Room, then Site, then Zone | E10: Following dropdown switches between Room/Site/Zone pickers and clears prior selection | F10: P2 | G10: Regression | H10: Playwright | I10: Not Tested
A11: INC-007 | B11: Create | C11: Priority computed from Impact x Urgency | D11: 1. Select Impact High + Urgency Medium (and other combos) | E11: Priority badge recomputes per the ITIL-style matrix (e.g. High+Medium=MODERATE); badge colour matches priority | F11: P1 | G11: Regression | H11: Playwright | I11: Not Tested
A12: INC-008 | B12: Create | C12: Auto-Resolve checkbox | D12: 1. Tick 'Auto-resolve when all associated alerts are resolved' 2. Create incident with associated alerts; resolve all alerts | E12: Incident automatically resolves once every associated alert is resolved | F12: P1 | G12: Regression | H12: Manual | I12: Not Tested
A13: INC-009 | B13: Create | C13: Step 2 — Associated Alerts | D13: 1. Complete step 1 > Next 2. Search/select alerts to associate 3. Create | E13: Alert picker lists/filters active alerts; created incident shows associations under its Associated Alerts tab | F13: P1 | G13: Regression | H13: Playwright | I13: Not Tested
A14: INC-010 | B14: Create | C14: Created incident appears in list + ServiceNow | D14: 1. Create a test incident (dev) | E14: Row appears in ACTIVE with NEW state; if ServiceNow integration enabled an INC number is allocated and synchronised | F14: P1 | G14: Regression | H14: Manual | I14: Not Tested
A15: INC-011 | B15: Detail | C15: Incident detail layout | D15: 1. Click an incident row | E15: Route /hotlist/incidents/detail/{INC#}; priority badge + title banner; tabs Information | Associated Alerts | Comments; Incident Details card shows source badge (ServiceNow), Incident Time, ID link, Category, Assigned To, Assignment Group, State, Impact, Urgency, Priority, Description; Room Details panel loads. KNOWN ISSUE: Room Details may hang 'Loading room details...'; SN description may show raw JSONata template | F15: P1 | G15: Regression | H15: Playwright | I15: Not Tested
A16: INC-012 | B16: Detail | C16: Edit Information | D16: 1. Click Edit Information 2. Change Assigned To / State / Description; save | E16: Editable fields update; Last Updated changes; edits sync to ServiceNow where applicable | F16: P1 | G16: Regression | H16: Manual | I16: Not Tested
... A27: INC-023 | B27: Comments | C27: Comment add/edit/delete CRUD | D27: 1. Add a comment; edit it; delete it (per RFC I5) | E27: Full CRUD works with author+timestamp; count badge updates; sync to ITSM if applicable | F27: P2 | G27: Regression | H27: Playwright | I27: Not Tested

Sheet Vitals
A1: Vitals — Regression Tests
A2: Vitals dashboards: Infrastructure, Rooms, Network, Pulse, Sight, custom
A4: Test ID | B4: Category | C4: Test Case | D4: Steps | E4: Expected Result | F4: Priority | G4: Type | H4: Automation | I4: Status | J4: Tested By | K4: Date | L4: Notes / Defect
A5: VIT-001 | B5: Common | C5: Time range selector on every Vitals view | D5: 1. Open each Vitals view 2. Change 'Past 24 hours' to other ranges | E5: All charts re-query for the selected window; axis labels update; selection persists while navigating between views | F5: P1 | G5: Regression | H5: Playwright | I5: Not Tested
A6: VIT-002 | B6: Common | C6: Refresh button | D6: 1. Click Refresh on any Vitals view | E6: All visualisations refetch; spinners resolve; Last Updated advances | F6: P2 | G6: Regression | H6: Playwright | I6: Not Tested
A7: VIT-003 | B7: Common | C7: Fullscreen expand | D7: 1. Click expand icon | E7: Dashboard enters fullscreen/kiosk mode; exit restores normal layout | F7: P3 | G7: Regression | H7: Playwright | I7: Not Tested
A8: VIT-004 | B8: Infrastructure | C8: View loads without errors in time | D8: 1. Open Vitals > Infrastructure | E8: Loads < 10s; no auth/index errors; KPIs Avg CPU, Avg Memory, Avg Storage, Hosts Online (n/m) populated | F8: P1 | G8: Smoke | H8: Playwright | I8: Not Tested
A9: VIT-005 | B9: Infrastructure | C9: All visualisations render with data | D9: 1. Scroll through view | E9: All Time CPU / Memory / Storage charts (per-host legend), Innomesh Healthcheck Response Time (all zones: Cluster A/B/C, Staging, Parking Lot), Host Response Time all render with plotted data | F9: P1 | G9: Regression | H9: Playwright | I9: Not Tested
A10: VIT-006 | B10: Infrastructure | C10: Real Time Host Vitals table sanity | D10: 1. Inspect host table | E10: Each tenant host listed: CPU%, Memory%, Storage%, Uptime(days), Active badge, Zone; values 0-100%, uptime plausible; row count matches host count (no cross-tenant hosts) | F10: P1 | G10: Regression | H10: Manual | I10: Not Tested
A11: VIT-007 | B11: Infrastructure | C11: VC-4 Service Vitals | D11: 1. Inspect VC-4 table | E11: Hosts running VC-4 listed with Uptime, Status RUNNING/STOPPED badge, Zone; status matches actual service state | F11: P2 | G11: Regression | H11: Manual | I11: Not Tested
A12: VIT-008 | B12: Vitals Rooms | C12: Rooms vitals view loads | D12: 1. Open Vitals > Rooms | E12: KPIs Rooms Powered On / Rooms Occupied; charts Room Powered On %, Room Occupancy %, Rooms Powered On and Occupied by Zone; Room Vitals table lists every tenancy room with maintenance badge | F12: P1 | G12: Regression | H12: Playwright | I12: Not Tested
A13: VIT-009 | B13: Vitals Rooms | C13: Counts correlate with tenancy | D13: 1. Compare Rooms Powered On/Occupied numbers with environment (start a room via XPanel in DEV only) | E13: Counts change when rooms power on/become occupied; never exceed total rooms in tenancy | F13: P1 | G13: Regression | H13: Manual | I13: Not Tested
A14: VIT-010 | B14: Vitals Rooms | C14: Empty data handling | D14: 1. View with a site filter having no active rooms | E14: Charts show 'No data available' placeholders; KPIs show dash/zero; no errors | F14: P2 | G14: Edge | H14: Playwright | I14: Not Tested
A15: VIT-011 | B15: Network | C15: Network view structure | D15: 1. Open Vitals > Network | E15: KPIs Total HTTP / DNS / TLS / Error Rate; charts Transaction Types, HTTP Transactions, DNS Transactions, TLS Sessions, Errors vs Successful, Errors Count Over Time, Latency Histogram, Response Times Distribution all render (or coherent empty states) | F15: P2 | G15: Regression | H15: Playwright | I15: Not Tested
A16: VIT-012 | B16: Pulse | C16: Pulse view structure | D16: 1. Open Vitals > Pulse | E16: Monitors Status, Pings Over Time, Monitors List, Median Device Response Time (+ per Zone) render; monitor list matches configured Pulse monitors; response times plausible | F16: P2 | G16: Regression | H16: Playwright | I16: Not Tested
... A25: VIT-021 | B25: Custom | C25: Custom dashboards from tenant config | D25: 1. Configure a custom Vitals dashboard (useCustomDashboards('Vitals')) 2. Verify tab appears with custom ID route /vitals/{customId} | E25: Custom tabs render from uiSettings tabLabels with .show flag + ip-vitals-custom permission; removing config removes tab | F25: P2 | G25: Regression | H25: Manual | I25: Not Tested

Sheet Insights
A1: Insights — Regression Tests
A2: Analytics dashboards incl. Consumption (billing) and custom insights
A4: Test ID | B4: Category | C4: Test Case | D4: Steps | E4: Expected Result | F4: Priority | G4: Type | H4: Automation | I4: Status | J4: Tested By | K4: Date | L4: Notes / Defect
A5: INS-001 | B5: Common | C5: Time range + refresh on all Insights views | D5: 1. Open each Insights view 2. Change 'Past 3 days' range; click Refresh | E5: Charts re-query; selection applies per view; no errors | F5: P1 | G5: Regression | H5: Playwright | I5: Not Tested
A6: INS-002 | B6: Rooms | C6: Insights Rooms visualisations | D6: 1. Open Insights > Rooms | E6: Room Types, Room Usage, Rooms With Most Interactions, Room Powered On Over Time, Room Age, Total Rooms Over Time render with data or clean empty state | F6: P2 | G6: Regression | H6: Playwright | I6: Not Tested
A7: INS-003 | B7: Usage | C7: Insights Usage visualisations | D7: 1. Open Insights > Usage | E7: Source Usage %, Display Usage, Source Usage, Most Used Devices, Source Usage Over Time, Most Common User Interactions render; 'No data available' when no usage telemetry | F7: P2 | G7: Regression | H7: Playwright | I7: Not Tested
A8: INS-004 | B8: Alerts | C8: Insights Alerts dashboard | D8: 1. Open Insights > Alerts | E8: NEW ALERTS KPI; charts Alerts By Severity/Zone/Category, Active Alerts Over Time, Alerts Created Over Time, Alerts By Room, Alerts By Device Type; Alerts History table (Created, Room, Zone, Device, Category, Severity, Resolved) paginates 15/page up to 200 | F8: P1 | G8: Regression | H8: Playwright | I8: Not Tested
A9: INS-005 | B9: Alerts | C9: KPI consistency with Hotlist | D9: 1. Compare NEW ALERTS for the selected period vs Hotlist history | E9: Counts consistent for equivalent period/filters; severity split matches | F9: P2 | G9: Regression | H9: Manual | I9: Not Tested
A10: INS-006 | B10: Alerts | C10: History rows show full context | D10: 1. Inspect Alerts History rows | E10: Room/Zone/Device/Severity populated (not all '-'); Resolved Yes/No accurate | F10: P2 | G10: Regression | H10: Manual | I10: Not Tested
A11: INS-007 | B11: Proactive Support | C11: MTTR metrics | D11: 1. Open Insights > Proactive Support | E11: Avg Alert Resolution Time (Hours), Avg Alert Response Time (Minutes), Alerts Report Per Person render; person-level report reflects claim/resolve actors | F11: P2 | G11: Regression | H11: Manual | I11: Not Tested
A12: INS-008 | B12: Sight | C12: Sight insights | D12: 1. Open Insights > Sight | E12: Qty of Sight Enriched Assets KPI (matches enriched asset count), Sight Queries Over Time chart | F12: P3 | G12: Regression | H12: Playwright | I12: Not Tested
A13: INS-009 | B13: Ops | C13: Ops insights + trigger history | D13: 1. Open Insights > Ops | E13: Ops Actions Triggered Over Time, Most Triggered Ops Actions, Rooms with Most Ops Actions, Top 10 Ops Users; Ops Trigger History table (Action, Room, User, Timestamp) pages 10/50; automation-triggered actions show user 'Automation' | F13: P2 | G13: Regression | H13: Playwright | I13: Not Tested
A14: INS-010 | B14: Consumption | C14: Consumption/licensing dashboard | D14: 1. Open Insights > Consumption | E14: KPIs Active Rooms, Rooms Added/Removed in period, Net Change, Peak Day Count; charts Total Rooms Over Time (stacked by site), Tier Distribution, Site Breakdown by Month, Rooms by Site & Tier, Room Changes Heatmap, Room Lifespan Timeline, Month-over-Month Changes, Room First Seen, Room Age; Room Details sortable table | F14: P1 | G14: Regression | H14: Playwright | I14: Not Tested
A15: INS-011 | B15: Consumption | C15: Billing-relevant accuracy | D15: 1. Cross-check Active Rooms + tier split against known tenancy subscription | E15: Room counts and tier breakdown match billing records — this drives invoicing; flag any discrepancy as critical | F15: P1 | G15: Regression | H15: Manual | I15: Not Tested
A16: INS-012 | B16: Custom | C16: ECU Custom Insight / INPOD | D16: 1. Open tenant-custom insights | E16: Custom dashboards render their configured panels; empty config shows clean page (title + range bar) without errors | F16: P3 | G16: Regression | H16: Playwright | I16: Not Tested
... A21: INS-017 | B21: Custom | C21: Custom Insights dashboards config-driven | D21: 1. Configure custom dashboard for Insights; check /insights/{customId} route + ip-insights-custom permission | E21: Custom tab renders; permission-gated; tab order follows tenant tabLabels | F21: P2 | G21: Regression | H21: Manual | I21: Not Tested

Sheet Assets
A1: Assets — Regression Tests
A2: Asset Register (25k+), asset detail tabs, Actions schedule/history
A4: Test ID | B4: Category | C4: Test Case | D4: Steps | E4: Expected Result | F4: Priority | G4: Type | H4: Automation | I4: Status | J4: Tested By | K4: Date | L4: Notes / Defect
A5: AST-001 | B5: List | C5: Asset Register loads at scale | D5: 1. Open Assets > Asset Register (tenancy ~25k assets) | E5: Table renders within acceptable time; count label accurate (e.g. '25408 assets'); pagination stable; no browser freeze | F5: P1 | G5: Smoke | H5: Playwright | I5: Not Tested
A6: AST-002 | B6: List | C6: Columns and sorting | D6: 1. Inspect columns; sort by Name, Category, Brand | E6: Columns Room, Name, Category, Brand, Model, IP Address, Power, Status, Compliance; sorting server-side across full dataset (not just current page) | F6: P1 | G6: Regression | H6: Playwright | I6: Not Tested
A7: AST-003 | B7: List | C7: Search assets | D7: 1. Search by asset name, model, room, IP | E7: Matching rows returned across the full register; count updates; clear restores | F7: P1 | G7: Regression | H7: Playwright | I7: Not Tested
A8: AST-004 | B8: List | C8: Saved views + column picker + export | D8: 1. Save a filtered view; recall; export | E8: Same machinery as Alerts (Recall/Save/Delete View); export contains filtered rows; large export runs as background op under bell | F8: P2 | G8: Regression | H8: Playwright | I8: Not Tested
A9: AST-005 | B9: List | C9: Edit (bulk) mode | D9: 1. Click Edit button 2. Modify an editable field (if enabled) 3. Save/cancel | E9: Edit mode toggles; edits validate and persist; cancel discards; permission-gated | F9: P2 | G9: Regression | H9: Manual | I9: Not Tested
A10: AST-006 | B10: List | C10: Row kebab View Details | D10: 1. Click kebab on a row > View Details | E10: Asset detail opens (/assets/detail/{roomId}/{assetId}) | F10: P1 | G10: Regression | H10: Playwright | I10: Not Tested
A11: AST-007 | B11: List | C11: Power / Status / Compliance values | D11: 1. Find assets with live status | E11: Power shows On/Off/NA badge; Status reflects monitoring state; Compliance reflects policy evaluation; '-' for non-monitored | F11: P2 | G11: Regression | H11: Manual | I11: Not Tested
A12: AST-008 | B12: Detail | C12: Detail tabs render | D12: 1. Open an asset detail | E12: Tabs Information, Status, Specifications, History, Alerts, Response Times, Files, Credentials, Actions all clickable; profile image or placeholder shown | F12: P1 | G12: Smoke | H12: Playwright | I12: Not Tested
A13: AST-009 | B13: Detail | C13: Information tab completeness | D13: 1. Open Information | E13: GENERAL section: name, asset_id, room (name+id), zone, site, brand, model, category, system name/id, user_group, hostname, created_at/last_updated; CONNECTIVITY: ip_address. Sensitive fields (password) never shown in plaintext | F13: P1 | G13: Regression | H13: Playwright | I13: Not Tested
A14: AST-010 | B14: Detail | C14: Status tab | D14: 1. Open Status tab | E14: Live status renders for monitored assets. KNOWN ISSUE (dev): crashes with 'e is not iterable' error boundary — must be fixed/regression-tested | F14: P1 | G14: Regression | H14: Playwright | I14: Not Tested
A15: AST-011 | B15: Detail | C15: Specifications per asset profile | D15: 1. Open Specifications on a profiled asset and an unprofiled one | E15: Profiled: spec fields render; Unprofiled: 'No specifications available for this asset profile.' | F15: P2 | G15: Regression | H15: Playwright | I15: Not Tested
A16: AST-012 | B16: Detail | C16: History / Alerts / Response Times tabs | D16: 1. Open each tab on an actively monitored asset | E16: History shows asset event log; Alerts lists alerts raised by this asset (click-through works); Response Times charts ping/poll latency | F16: P2 | G16: Regression | H16: Manual | I16: Not Tested
... A27: AST-023 | B27: Files | C27: Asset file upload/download via presigned URLs | D27: 1. Upload file on asset Files tab; download it; check URL expiry | E27: Presigned URL flow works (POST /asset/file, GET /asset/file); expired URLs fail gracefully; files listed with metadata | F27: P2 | G27: Regression | H27: Manual | I27: Not Tested

Sheet Information
A1: Information — Regression Tests
A2: Custom room-information summary views and inline editing
A4: Test ID | B4: Category | C4: Test Case | D4: Steps | E4: Expected Result | F4: Priority | G4: Type | H4: Automation | I4: Status | J4: Tested By | K4: Date | L4: Notes / Defect
A5: INF-001 | B5: Views | C5: Custom views render as tabs | D5: 1. Open Information page | E5: Configured summary views render as tabs (e.g. Demo View, Room Summary, WebCheckout); first tab loads by default | F5: P1 | G5: Smoke | H5: Playwright | I5: Not Tested
A6: INF-002 | B6: Views | C6: Per-view custom columns | D6: 1. Switch between tabs | E6: Each view shows its configured attribute columns (SLA, System ID, Timetable, Capture Device, area, Schematic PDF, etc.); horizontal scroll for wide sets; sortable | F6: P1 | G6: Regression | H6: Playwright | I6: Not Tested
A7: INF-003 | B7: Data | C7: Attribute links work | D7: 1. Click a Timetable URL and a Schematic PDF link | E7: External links open in new tab (shorturl + S3 attachment links valid, no 403/404) | F7: P2 | G7: Regression | H7: Manual | I7: Not Tested
A8: INF-004 | B8: Edit | C8: Inline edit (pencil) mode | D8: 1. Click pencil icon 2. Edit an attribute value; save 3. Re-load page | E8: Edit mode enables cell editing; saved value persists and is visible to other users; validation per attribute type (number/boolean/text) | F8: P1 | G8: Regression | H8: Manual | I8: Not Tested
A9: INF-005 | B9: Search | C9: Search rooms within a view | D9: 1. Type a room name | E9: Rows filter live; works in every view tab | F9: P2 | G9: Regression | H9: Playwright | I9: Not Tested
A10: INF-006 | B10: Views | C10: Saved views (Recall/Save) | D10: 1. Apply search/sort; save view; recall | E10: View machinery works as in other modules | F10: P3 | G10: Regression | H10: Playwright | I10: Not Tested
A11: INF-007 | B11: Sync | C11: Attribute changes propagate | D11: 1. Change a room attribute under Admin > Room Attributes (or via import) 2. Check Information view | E11: Information view reflects new attribute values/columns; Summary Views config drives which tabs exist | F11: P2 | G11: Regression | H11: Manual | I11: Not Tested
A12: INF-008 | B12: Permissions | C12: Information access gating | D12: 1. Login without Room Information permission | E12: Information nav hidden; URLs denied; edit mode requires elevated permission | F12: P1 | G12: Regression | H12: Manual | I12: Not Tested
A13: INF-009 | B13: Edit Rules | C13: Field editability matrix | D13: 1. Attempt inline edit on: Hyperlink, File, Image fields; smart attributes; sync_direction=Inbound fields; dynamic fields; plain text/enum fields | E13: Only non-Hyperlink/File/Image, non-smart, non-Inbound, non-dynamic fields are editable; enum fields show dropdown of enum values; others read-only with no edit affordance | F13: P1 | G13: Regression | H13: Playwright | I13: Not Tested
A14: INF-010 | B14: Links | C14: SecureLinks flag behaviour | D14: 1. Tenant with InformationDetailView.SecureLinks=true: open Files/Links section | E14: Links served as secured/presigned (POST /smp/download_files); without flag, direct URLs; no broken links either way | F14: P2 | G14: Regression | H14: Manual | I14: Not Tested
A15: INF-011 | B15: Sections | C15: Config-driven sections (Digital Signage / Web Checkout) | D15: 1. Toggle showDigitalSignage/showWebCheckout in tenant config 2. Open information detail | E15: Sections render only when configured; Web Checkout uses v1 API endpoints incl. sync (POST /room/{id}/webcheckout/sync); Timetable section appears only when timetable fields detected | F15: P2 | G15: Regression | H15: Manual | I15: Not Tested
A16: INF-012 | B16: Export | C16: Room fields CSV export request flow | D16: 1. Trigger CSV export (POST /smp/roomfields/csv/request) 2. Wait for completion | E16: Async export tracked (bell PROGRESS); file matches current view's rooms/fields; filename convention {tenant}-{date}-{type}.csv | F16: P2 | G16: Regression | H16: Manual | I16: Not Tested

Sheet Integrations
A1: Integrations — Regression Tests
A2: QSC Q-Sys, Microsoft Teams Room, Appspace
A4: Test ID | B4: Category | C4: Test Case | D4: Steps | E4: Expected Result | F4: Priority | G4: Type | H4: Automation | I4: Status | J4: Tested By | K4: Date | L4: Notes / Defect
A5: ITG-001 | B5: Q-Sys | C5: Global Logs tab | D5: 1. Open Integrations > QSC Q-Sys | E5: Tabs Global Logs | Global Events | Global Vitals; logs table (Date & Time, Room Name, Device IP, Message, Category, Source) with time-range selector (Last 1 Day) and saved views; 'No logs found' empty state | F5: P1 | G5: Smoke | H5: Playwright | I5: Not Tested
A6: ITG-002 | B6: Q-Sys | C6: Global Events tab | D6: 1. Click Global Events | E6: Events table (… Category, Severity) renders; search + export work; events correspond to Q-Sys cores in environment | F6: P2 | G6: Regression | H6: Playwright | I6: Not Tested
A7: ITG-003 | B7: Q-Sys | C7: Global Vitals tab | D7: 1. Click Global Vitals | E7: KPIs Q-SYS Devices / Total Faults / Total Warnings; charts CPU Usage %, Memory Usage %, Disk Usage %, CPU Temperature, Faults over Time, Warnings over Time; values match connected cores; clean empty states when none | F7: P2 | G7: Regression | H7: Playwright | I7: Not Tested
A8: ITG-004 | B8: Q-Sys | C8: Time range selector | D8: 1. Change 'Last 1 Day' range | E8: Logs/events/vitals re-query for window | F8: P2 | G8: Regression | H8: Playwright | I8: Not Tested
A9: ITG-005 | B9: Teams Room | C9: Device List | D9: 1. Open Integrations > Microsoft Teams Room | E9: Tabs Device List | Insights; table Microsoft Teams Room Name, Model, IP, MAC, Serial Number, Teams Admin Agent, Windows OS, Teams App, Activity State, Health Status (HEALTHY badge); device data matches Teams Admin Center | F9: P1 | G9: Regression | H9: Playwright | I9: Not Tested
A10: ITG-006 | B10: Teams Room | C10: Insights tab | D10: 1. Click Insights tab | E10: Teams Room analytics render (usage/health) without errors | F10: P2 | G10: Regression | H10: Manual | I10: Not Tested
A11: ITG-007 | B11: Appspace | C11: Appspace page loads its own module | D11: 1. Click Appspace in sidebar 2. Also deep-link /integrations/appspace directly | E11: Appspace integration UI renders (devices/content health). KNOWN ISSUE: deep link and even sidebar nav currently render the QSC Q-Sys module — regression-test the route fix | F11: P1 | G11: Regression | H11: Playwright | I11: Not Tested
A12: ITG-008 | B12: Routing | C12: Integration deep links after refresh | D12: 1. On each integration page press F5 | E12: Page reloads to the same integration (not Q-Sys); breadcrumb/title correct | F12: P1 | G12: Regression | H12: Playwright | I12: Not Tested
A13: ITG-009 | B13: Permissions | C13: Integrations visibility by permission | D13: 1. Login without integration management permission | E13: Integrations section hidden; URLs denied | F13: P1 | G13: Regression | H13: Manual | I13: Not Tested
A14: ITG-010 | B14: Config | C14: Integration with no configured connection | D14: 1. View an integration page in a tenancy without that integration configured | E14: Clean empty/CTA state, no stack traces | F14: P2 | G14: Edge | H14: Manual | I14: Not Tested
A15: ITG-011 | B15: Parity | C15: Cisco Webex / Zoom / Biamp SageVue presence (v3 parity) | D15: 1. v3 shipped Webex, Zoom, Biamp SageVue integrations; v4 permission constants exist (ip-integrations-cisco-webex/zoom/biamp-sagevue) 2. Check v4 tabs for tenants using them | E15: PARITY CHECK: integrations render for entitled tenants or the gap is documented as accepted delta in the parity catalogue | F15: P1 | G15: Regression | H15: Manual | I15: Not Tested
A16: ITG-012 | B16: MTR | C16: MTR data + actions flag | D16: 1. Open MTR tab (devices/insights/properties endpoints) 2. Tenant with mtr_actions_enabled=true: verify device actions | E16: Device list matches Teams admin data; insights/properties load; MTR actions appear only when alertConfig.mtr_actions_enabled | F16: P2 | G16: Regression | H16: Manual | I16: Not Tested
... A18: ITG-014 | B18: Appspace | C18: Appspace endpoints listing | D18: 1. Open Appspace tab (GET /integrations/appspace + /endpoints) | E18: Appspace devices/endpoints render; empty state when unconfigured; (blocked today by route-rendering bug BUG-002) | F18: P2 | G18: Regression | H18: Playwright | I18: Not Tested

Sheet Rooms
A1: Rooms — Regression Tests
A2: Rooms list and room support view
A4: Test ID | B4: Category | C4: Test Case | D4: Steps | E4: Expected Result | F4: Priority | G4: Type | H4: Automation | I4: Status | J4: Tested By | K4: Date | L4: Notes / Defect
A5: ROM-001 | B5: List | C5: Rooms list loads under All Sites | D5: 1. Open Rooms | E5: List loads within 30s budget; 'POWERED ON: n' badge + total room count accurate. KNOWN ISSUE (dev): 'Failed to load rooms — timeout of 30000ms exceeded' with Retry; must be perf-tested at production scale | F5: P1 | G5: Smoke | H5: Playwright | I5: Not Tested
A6: ROM-002 | B6: List | C6: Columns and default sort | D6: 1. Inspect table | E6: Columns Room, Zone, Site, Power, Type, Alerts; default sorted by Alerts desc; all columns sortable | F6: P1 | G6: Regression | H6: Playwright | I6: Not Tested
A7: ROM-003 | B7: List | C7: Search rooms | D7: 1. Search a room name | E7: Filtered server-side promptly; count and POWERED ON badge update for the filtered set | F7: P1 | G7: Regression | H7: Playwright | I7: Not Tested
A8: ROM-004 | B8: List | C8: Retry after load failure | D8: 1. If load fails, click Retry | E8: Retry re-issues the query; succeeds when backend healthy; no duplicated rows | F8: P2 | G8: Negative | H8: Playwright | I8: Not Tested
A9: ROM-005 | B9: List | C9: Saved views / column picker / export | D9: 1. Save a view, recall it, export | E9: Standard view machinery works; export matches filter | F9: P2 | G9: Regression | H9: Playwright | I9: Not Tested
A10: ROM-006 | B10: Support View | C10: Room support view opens | D10: 1. Click a room row (or room link from an alert/asset) | E10: Room support view opens with room header (power/occupancy state) and tabs for Hotlist, Assets, History, Resources, Schedule (per v4 design); breadcrumb back to Rooms | F10: P1 | G10: Smoke | H10: Playwright | I10: Not Tested
A11: ROM-007 | B11: Support View | C11: Room Hotlist tab | D11: 1. Open room's Hotlist tab | E11: Only this room's active alerts listed; claiming/resolving here reflects in global Hotlist | F11: P1 | G11: Regression | H11: Playwright | I11: Not Tested
A12: ROM-008 | B12: Support View | C12: Room Assets tab + live status | D12: 1. Open Assets tab 2. Open an asset's live status | E12: All room assets listed with category/status; live status streams current device state for online assets | F12: P1 | G12: Regression | H12: Manual | I12: Not Tested
A13: ROM-009 | B13: Support View | C13: Room History tab | D13: 1. Open History tab | E13: Room event history (power, occupancy, alerts) in chronological order; filters work | F13: P2 | G13: Regression | H13: Manual | I13: Not Tested
A14: ROM-010 | B14: Support View | C14: Room Resources tab | D14: 1. Open Resources tab | E14: Room resources/attachments (schematics, docs) listed and downloadable | F14: P2 | G14: Regression | H14: Manual | I14: Not Tested
A15: ROM-011 | B15: Support View | C15: Room Schedule tab | D15: 1. Open Schedule tab on a calendar-integrated room | E15: Upcoming bookings render from calendar integration; correct timezone | F15: P2 | G15: Regression | H15: Manual | I15: Not Tested
A16: ROM-012 | B16: Support View | C16: Ellipsis/kebab room actions | D16: 1. Open room kebab menu | E16: Room-level actions (e.g. maintenance mode, edit info) listed per permissions; maintenance toggle suppresses room alerts and shows in Vitals > Rooms maintenance count | F16: P1 | G16: Regression | H16: Manual | I16: Not Tested
... A25: ROM-021 | B25: Permissions | C25: Launch Remote UI permission | D25: 1. User without ip-rooms-launch-remote-ui opens room detail | E25: Remote UI launcher hidden/disabled; with permission, remote URL (remote.{tenant}.{domain}?roomid=...) opens | F25: P2 | G25: Regression | H25: Manual | I25: Not Tested

Sheet Axis AI
A1: Axis AI — Regression Tests
A2: Axis AI chat, saved insights, data scoping
A4: Test ID | B4: Category | C4: Test Case | D4: Steps | E4: Expected Result | F4: Priority | G4: Type | H4: Automation | I4: Status | J4: Tested By | K4: Date | L4: Notes / Defect
A5: AXI-001 | B5: Chat | C5: Landing state | D5: 1. Open Axis AI | E5: Chat tab active; CONNECTED badge; welcome message + example prompt buttons; input with send button | F5: P1 | G5: Smoke | H5: Playwright | I5: Not Tested
A6: AXI-002 | B6: Chat | C6: Example prompt buttons | D6: 1. Click 'What rooms have alerts?' | E6: Prompt submitted; Axis responds with data consistent with Hotlist (rooms with active alerts) | F6: P1 | G6: Regression | H6: Manual | I6: Not Tested
A7: AXI-003 | B7: Chat | C7: Natural language data query with visualisation | D7: 1. Ask 'Show me the alert trend over the last two months' | E7: Response includes a rendered chart/table; values consistent with Insights > Alerts | F7: P1 | G7: Regression | H7: Manual | I7: Not Tested
A8: AXI-004 | B8: Chat | C8: Slash commands and /axis-catalog | D8: 1. Type '/' in input 2. Run /axis-catalog | E8: Slash command menu appears; /axis-catalog lists available datasets and preset questions | F8: P2 | G8: Regression | H8: Playwright | I8: Not Tested
A9: AXI-005 | B9: Chat | C9: Nonsense/out-of-scope question | D9: 1. Ask something unrelated (e.g. weather) | E9: Graceful refusal/redirect to platform data scope; no crash or hallucinated tenant data | F9: P2 | G9: Negative | H9: Manual | I9: Not Tested
A10: AXI-006 | B10: Chat | C10: Clear conversation | D10: 1. Click trash icon top-right | E10: Conversation clears back to welcome state (with confirm if destructive) | F10: P3 | G10: Regression | H10: Playwright | I10: Not Tested
A11: AXI-007 | B11: Saved Insights | C11: Save and recall an insight | D11: 1. Generate a chart answer 2. Save it 3. Open Saved Insights tab | E11: Saved item listed with name/date; reopening re-renders the visualisation; delete works | F11: P2 | G11: Regression | H11: Manual | I11: Not Tested
A12: AXI-008 | B12: Security | C12: Data scoping in AI answers | D12: 1. Ask for data as a user-group-restricted user | E12: Responses only include rooms/devices within the user's permission scope — no leakage across user groups/tenants | F12: P1 | G12: Regression | H12: Manual | I12: Not Tested
A13: AXI-009 | B13: Resilience | C13: AI service disconnected | D13: 1. Open Axis AI when backend unavailable (dev simulation) | E13: Status badge reflects disconnected; input disabled or queued with clear messaging | F13: P3 | G13: Edge | H13: Manual | I13: Not Tested
A14: AXI-010 | B14: Persistence | C14: Saved insights caps + in-memory store limits | D14: 1. Save >50 insights; append >200 query-log entries 2. Restart BFF (dev) | E14: Caps enforced (50 insights deduped by messageId, 200 log entries); KNOWN LIMITATION: store is in-memory per user — data lost on BFF restart; verify behaviour is acceptable/documented before GA | F14: P2 | G14: Edge | H14: API | I14: Not Tested
A15: AXI-011 | B15: Connection | C15: Connection state machine | D15: 1. Observe badge states: connected / disconnected / reconnecting / service_unavailable (kill WS, restore) | E15: Status badge transitions correctly; reconnect recovers; queries blocked or queued while disconnected with clear messaging | F15: P2 | G15: Regression | H15: Manual | I15: Not Tested
A16: AXI-012 | B16: Replay | C16: Query replay from saved insight | D16: 1. Save an insight; open Saved Insights; click replay | E16: Original query re-submitted into chat (pendingQuery), new response generated; usage logged to query-log | F16: P3 | G16: Regression | H16: Manual | I16: Not Tested

Sheet Administration
A1: Administration — Regression Tests
A2: Audit logs, asset profiles/drivers/policies, settings, users, room attributes, import/export, automation, incident rules
A4: Test ID | B4: Category | C4: Test Case | D4: Steps | E4: Expected Result | F4: Priority | G4: Type | H4: Automation | I4: Status | J4: Tested By | K4: Date | L4: Notes / Defect
A5: ADM-001 | B5: Audit Logs | C5: Audit logs page loads | D5: 1. Open Administration > Audit Logs | E5: Log table with filters loads. KNOWN ISSUE (dev): crashes 'A <Select.Item /> must have a value prop that is not an empty string' — regression-test the fix; verify error boundary resets when navigating away (currently sticks until Try again) | F5: P1 | G5: Regression | H5: Playwright | I5: Not Tested
A6: ADM-002 | B6: Audit Logs | C6: Actions are audited | D6: 1. Claim an alert, edit an attribute, sign in/out 2. Check audit logs | E6: Each action recorded with actor, timestamp, entity and action type; filterable by user/date/type | F6: P1 | G6: Regression | H6: Manual | I6: Not Tested
A7: ADM-003 | B7: Assets Admin | C7: Asset profile tabs render | D7: 1. Open Administration > Assets | E7: Tabs Asset Profiles | Space VC Drivers | Space CE Drivers | Sight Drivers | Ops Actions | Pulse Drivers | Asset Policies | Asset Fields; profile table columns Profile Name, Type, Brand, Model, ID Convention, Name Convention | F7: P1 | G7: Smoke | H7: Playwright | I7: Not Tested
A8: ADM-004 | B8: Assets Admin | C8: Create asset profile | D8: 1. Click + Create Profile 2. Complete and save (dev) | E8: Profile created and listed; assets matching ID convention pick up profile (specs/actions become available on asset detail) | F8: P1 | G8: Regression | H8: Manual | I8: Not Tested
A9: ADM-005 | B9: Assets Admin | C9: Driver tabs (Space VC/CE, Sight, Pulse) | D9: 1. Open each driver tab | E9: Driver lists render with version/status; create/edit driver config flows validate required fields | F9: P2 | G9: Regression | H9: Manual | I9: Not Tested
A10: ADM-006 | B10: Assets Admin | C10: Ops Actions definitions | D10: 1. Open Ops Actions tab 2. Create/edit an action (dev) | E10: Action defined with parameters; becomes triggerable from matching assets' Actions tab and Automation policies | F10: P2 | G10: Regression | H10: Manual | I10: Not Tested
A11: ADM-007 | B11: Assets Admin | C11: Asset Policies (compliance) | D11: 1. Open Asset Policies 2. Define a policy (e.g. DHCP must be disabled) | E11: Policy evaluation flags non-compliant assets (Compliance column in register) and raises Policy Compliance alerts (cf. 'DHCP Enabled is True' demo alert) | F11: P1 | G11: Regression | H11: Manual | I11: Not Tested
A12: ADM-008 | B12: Assets Admin | C12: Asset Fields (custom fields) | D12: 1. Open Asset Fields; add a custom field | E12: Field appears on asset records; values editable and exportable | F12: P2 | G12: Regression | H12: Manual | I12: Not Tested
A13: ADM-009 | B13: Settings | C13: Change Mode toggle | D13: 1. Open Administration > Settings 2. Enable Change Mode | E13: Toggle persists; SLA tracking halted during change window (outages excluded from SLA metrics); banner/indicator communicates active change mode; disable restores tracking | F13: P1 | G13: Regression | H13: Manual | I13: Not Tested
A14: ADM-010 | B14: Settings | C14: ServiceNow Auto Incident Creation toggle | D14: 1. Toggle the setting | E14: When ON: SN incidents auto-create/resolve 15 min after alert create/resolve. When OFF: no automatic SN incidents | F14: P1 | G14: Regression | H14: Manual | I14: Not Tested
A15: ADM-011 | B15: Users | C15: Users tab listing | D15: 1. Open Administration > Users | E15: Tabs Users | User Groups | Roles | SAML Roles | App Clients; user table: Given/Family Name, Email, Roles, User Group, SSO Provider, Date Created, Terms (accepted?); search + export | F15: P1 | G15: Smoke | H15: Playwright | I15: Not Tested
A16: ADM-012 | B16: Users | C16: Create/edit user and assign roles | D16: 1. Create a test user (dev); assign role + user group | E16: User created; receives access per role on next login; edits audited | F16: P1 | G16: Regression | H16: Manual | I16: Not Tested
... A44: ADM-040 | B44: Audit | C44: Login/logout audit events | D44: 1. Login and logout (POST /user/login, /user/logout fired) 2. Check Audit Logs | E44: Both events recorded with user, timestamp, session; visible in admin audit log with filters | F44: P2 | G44: Regression | H44: Playwright | I44: Not Tested

Sheet RBAC & Permissions
A1: RBAC & Permissions — Regression Tests
A2: Role/permission visibility, user-group scoping, server-side enforcement
A4: Test ID | B4: Category | C4: Test Case | D4: Steps | E4: Expected Result | F4: Priority | G4: Type | H4: Automation | I4: Status | J4: Tested By | K4: Date | L4: Notes / Defect
